Workbook
Name Slicer_Category1: #N/A
Name Slicer_Item_Name: #N/A

Sheet Master Barang
A1: Item Code | B1: Item Name | C1: Category | D1: Brand | E1: Unit | F1: Supplier | G1: Purchase Price | H1: Selling Price | I1: Reorder Point | J1: Maximum Stock | K1: Minimum Stock
A2: BEV001 | B2: Coca Cola Beverage Variant 1 | C2: Beverage | D2: Coca Cola | E2: Bottle | F2: PT Supplier 26 | G2: 14300 | H2: 18100 | I2: 150 | J2: 900 | K2: 75
A3: BEV002 | B3: Aqua Beverage Variant 2 | C3: Beverage | D3: Aqua | E3: Bottle | F3: PT Supplier 22 | G3: 78700 | H3: 91500 | I3: 400 | J3: 2000 | K3: 200
A4: BEV003 | B4: Sosro Beverage Variant 3 | C4: Beverage | D4: Sosro | E4: Bottle | F4: PT Supplier 02 | G4: 75500 | H4: 88400 | I4: 40 | J4: 160 | K4: 20
A5: BEV004 | B5: Aqua Beverage Variant 4 | C5: Beverage | D5: Aqua | E5: Bottle | F5: PT Supplier 21 | G5: 73700 | H5: 85700 | I5: 180 | J5: 900 | K5: 90
A6: BEV005 | B6: Aqua Beverage Variant 5 | C6: Beverage | D6: Aqua | E6: Bottle | F6: PT Supplier 33 | G6: 43600 | H6: 51500 | I6: 80 | J6: 320 | K6: 40
A7: BEV006 | B7: Pocari Beverage Variant 6 | C7: Beverage | D7: Pocari | E7: Bottle | F7: PT Supplier 26 | G7: 60200 | H7: 70500 | I7: 100 | J7: 500 | K7: 50
A8: BEV007 | B8: Sosro Beverage Variant 7 | C8: Beverage | D8: Sosro | E8: Bottle | F8: PT Supplier 26 | G8: 34900 | H8: 41400 | I8: 500 | J8: 2000 | K8: 250
A9: BEV008 | B9: Aqua Beverage Variant 8 | C9: Beverage | D9: Aqua | E9: Bottle | F9: PT Supplier 24 | G9: 48200 | H9: 59200 | I9: 20 | J9: 100 | K9: 10
A10: BEV009 | B10: Aqua Beverage Variant 9 | C10: Beverage | D10: Aqua | E10: Bottle | F10: PT Supplier 10 | G10: 37300 | H10: 46700 | I10: 100 | J10: 400 | K10: 50
A11: BEV010 | B11: Coca Cola Beverage Variant 10 | C11: Beverage | D11: Coca Cola | E11: Bottle | F11: PT Supplier 10 | G11: 16400 | H11: 19700 | I11: 180 | J11: 1080 | K11: 90
A12: BEV011 | B12: Pocari Beverage Variant 11 | C12: Beverage | D12: Pocari | E12: Bottle | F12: PT Supplier 05 | G12: 83400 | H12: 105600 | I12: 150 | J12: 900 | K12: 75
A13: BEV012 | B13: Pocari Beverage Variant 12 | C13: Beverage | D13: Pocari | E13: Bottle | F13: PT Supplier 34 | G13: 10600 | H13: 13100 | I13: 40 | J13: 160 | K13: 20
... A201: BAB020 | B201: Zwitsal Baby Care Variant 20 | C201: Baby Care | D201: Zwitsal | E201: Pack | F201: PT Supplier 11 | G201: 57600 | H201: 73300 | I201: 400 | J201: 1600 | K201: 200

Sheet Stok Awal
A1: Item Code | B1: Beginning Stock
A2: BEV001 | B2: 476
A3: BEV002 | B3: 1798
A4: BEV003 | B4: 140
A5: BEV004 | B5: 894
A6: BEV005 | B6: 174
A7: BEV006 | B7: 369
A8: BEV007 | B8: 1802
A9: BEV008 | B9: 46
A10: BEV009 | B10: 361
A11: BEV010 | B11: 567
A12: BEV011 | B12: 626
A13: BEV012 | B13: 193
... A201: BAB020 | B201: 1614

Sheet Dashboard
A3: Category Selector | E3: Total Received | I3: Total Dispatched | N3: Total Avaibility | R3: Monthly Available Stock Trend | Z3: Product Selector
E12: 10 Lowest Stock Product | Z12: Stock Performance Overview
E13: Product ID | H13: Product Name | M13: Category | P13: Quantity Available | T13: Re-Order Level | W13: Status
E14: =Data_Preparation!M3 -> DAR015 | H14: =Data_Preparation!N3 -> Ultra Milk Dairy Variant 15 | M14: =Data_Preparation!O3 -> Dairy | P14: =Data_Preparation!Q3 -> 3 | T14: =Data_Preparation!R3 -> 40 | W14: =Data_Preparation!P3 -> Reorder Required
E15: =Data_Preparation!M4 -> INS003 | H15: =Data_Preparation!N4 -> Indomie Instant Food Variant 3 | M15: =Data_Preparation!O4 -> Instant Food | P15: =Data_Preparation!Q4 -> 78 | T15: =Data_Preparation!R4 -> 120 | W15: =Data_Preparation!P4 -> Reorder Required
E16: =Data_Preparation!M5 -> SNK010 | H16: =Data_Preparation!N5 -> Taro Snack Variant 10 | M16: =Data_Preparation!O5 -> Snack | P16: =Data_Preparation!Q5 -> 94 | T16: =Data_Preparation!R5 -> 60 | W16: =Data_Preparation!P5 -> Safe Stock Level
E17: =Data_Preparation!M6 -> DAR019 | H17: =Data_Preparation!N6 -> Ultra Milk Dairy Variant 19 | M17: =Data_Preparation!O6 -> Dairy | P17: =Data_Preparation!Q6 -> 133 | T17: =Data_Preparation!R6 -> 20 | W17: =Data_Preparation!P6 -> Overstock
E18: =Data_Preparation!M7 -> PER015 | H18: =Data_Preparation!N7 -> Sunsilk Personal Care Variant 15 | M18: =Data_Preparation!O7 -> Personal Care | P18: =Data_Preparation!Q7 -> 193 | T18: =Data_Preparation!R7 -> 60 | W18: =Data_Preparation!P7 -> Safe Stock Level
E19: =Data_Preparation!M8 -> BAB008 | H19: =Data_Preparation!N8 -> Zwitsal Baby Care Variant 8 | M19: =Data_Preparation!O8 -> Baby Care | P19: =Data_Preparation!Q8 -> 222 | T19: =Data_Preparation!R8 -> 200 | W19: =Data_Preparation!P8 -> Safe Stock Level
E20: =Data_Preparation!M9 -> BEV003 | H20: =Data_Preparation!N9 -> Sosro Beverage Variant 3 | M20: =Data_Preparation!O9 -> Beverage | P20: =Data_Preparation!Q9 -> 256 | T20: =Data_Preparation!R9 -> 40 | W20: =Data_Preparation!P9 -> Overstock
E21: =Data_Preparation!M10 -> BEV032 | H21: =Data_Preparation!N10 -> Aqua Beverage Variant 32 | M21: =Data_Preparation!O10 -> Beverage | P21: =Data_Preparation!Q10 -> 276 | T21: =Data_Preparation!R10 -> 100 | W21: =Data_Preparation!P10 -> Safe Stock Level
E22: =Data_Preparation!M11 -> INS025 | H22: =Data_Preparation!N11 -> Indomie Instant Food Variant 25 | M22: =Data_Preparation!O11 -> Instant Food | P22: =Data_Preparation!Q11 -> 277 | T22: =Data_Preparation!R11 -> 60 | W22: =Data_Preparation!P11 -> Safe Stock Level
E23: =Data_Preparation!M12 -> SNK030 | H23: =Data_Preparation!N12 -> Qtela Snack Variant 30 | M23: =Data_Preparation!O12 -> Snack | P23: =Data_Preparation!Q12 -> 278 | T23: =Data_Preparation!R12 -> 100 | W23: =Data_Preparation!P12 -> Safe Stock Level

Sheet Data_Preparation
A1: 📊 Data Stock Berdasarkan Product | M1: Bottom 10 Stock | V1: KPI | Z1: Stock Performance Overview | AE1: Monthly Stock Avaibility
A2: Item Code | B2: Item Name | C2: Category | D2: Stock Awal | E2: Qty Received | F2: Qty Dispatched | G2: Qty Available | H2: Re Order Point | I2: Minimum Stock | J2: Maximum Stock | K2: Stock Status | M2: Item Code | N2: Item Name | O2: Category | P2: Stock Status | Q2: Sum of Qty Available | R2: Sum of Re Order Point | S2: Sum of Qty Dispatched | T2: Sum of Qty Received | V2: Total Received | W2: Total Dispatched | X2: Total Available | Z2: Total SKU | AA2: Safe Stock | AB2: Reorder Required | AC2: Overstock | AE2: Month | AF2: Stock Available | AG2: Qty Received Monthly | AH2: Qty Dispatched Monthly | AI2: Total Avaibility
A3: BEV001 | B3: =VLOOKUP(current_stock[[#This Row],[Item Code]],master_barang[],2,FALSE) -> Coca Cola Beverage Variant 1 | C3: =VLOOKUP(current_stock[[#This Row],[Item Code]],master_barang[],3,FALSE) -> Beverage | D3: =VLOOKUP(current_stock[[#This Row],[Item Code]],stok_awal[],2,FALSE) -> 476 | E3: =SUMIF(Barang_Masuk!D:D,A3,Barang_Masuk!F:F) -> 450 | F3: =SUMIF(Barang_Keluar!D:D,A3,Barang_Keluar!F:F) -> 220 | G3: =current_stock[[#This Row],[Stock Awal]]+current_stock[[#This Row],[Qty Received]]-current_stock[[#This Row],[Qty Dispatched]] -> 706 | H3: =VLOOKUP(current_stock[[#This Row],[Item Code]],master_barang[],9,FALSE) -> 150 | I3: =VLOOKUP(current_stock[[#This Row],[Item Code]],master_barang[],11,FALSE) -> 75 | J3: =VLOOKUP(current_stock[[#This Row],[Item Code]],master_barang[],10,FALSE) -> 900 | K3: =IF(current_stock[[#This Row],[Qty Available]]<current_stock[[#This Row],[Re Order Point]],"Reorder Required",IF(current_stock[[#This Row],[Qty Available]]>current_stock[[#This Row],[Maximum Stock]],"Overstock","Safe Stock Level")) -> Safe Stock Level | M3: DAR015 | N3: Ultra Milk Dairy Variant 15 | O3: Dairy | P3: Reorder Required | Q3: 3 | R3: 40 | S3: 286 | T3: 180 | V3: =SUM(T3:T203) -> 130900 | W3: =SUM(S3:S203) -> 64027 | X3: =SUM(Q3:Q202) -> 191381 | Z3: =COUNTA(P3:P202) -> 200 | AA3: =COUNTIF(P:P,"Safe Stock Level") -> 66 | AB3: =COUNTIF(P3:P202,"Reorder Required") -> 2 | AC3: =COUNTIF(P3:P202,"Overstock") -> 132 | AE3: 46023 | AF3: =SUM('Stok Awal'!B:B) -> 124508 | AG3: =SUMIFS(Barang_Masuk!F:F,Barang_Masuk!B:B,">="&DATE(2026,1,1),Barang_Masuk!B:B,"<"&DATE(2026,2,1)) -> 21260 | AH3: =SUMIFS(Barang_Keluar!F:F,Barang_Keluar!B:B,">="&DATE(2026,1,1),Barang_Keluar!B:B,"<"&DATE(2026,2,1)) -> 10231 | AI3: =AF3+AG3-AH3 -> 135537
A4: BEV002 | B4: =VLOOKUP(current_stock[[#This Row],[Item Code]],master_barang[],2,FALSE) -> Aqua Beverage Variant 2 | C4: =VLOOKUP(current_stock[[#This Row],[Item Code]],master_barang[],3,FALSE) -> Beverage | D4: =VLOOKUP(current_stock[[#This Row],[Item Code]],stok_awal[],2,FALSE) -> 1798 | E4: =SUMIF(Barang_Masuk!D:D,A4,Barang_Masuk!F:F) -> 580 | F4: =SUMIF(Barang_Keluar!D:D,A4,Barang_Keluar!F:F) -> 256 | G4: =current_stock[[#This Row],[Stock Awal]]+current_stock[[#This Row],[Qty Received]]-current_stock[[#This Row],[Qty Dispatched]] -> 2122 | H4: =VLOOKUP(current_stock[[#This Row],[Item Code]],master_barang[],9,FALSE) -> 400 | I4: =VLOOKUP(current_stock[[#This Row],[Item Code]],master_barang[],11,FALSE) -> 200 | J4: =VLOOKUP(current_stock[[#This Row],[Item Code]],master_barang[],10,FALSE) -> 2000 | K4: =IF(current_stock[[#This Row],[Qty Available]]<current_stock[[#This Row],[Re Order Point]],"Reorder Required",IF(current_stock[[#This Row],[Qty Available]]>current_stock[[#This Row],[Maximum Stock]],"Overstock","Safe Stock Level")) -> Overstock | M4: INS003 | N4: Indomie Instant Food Variant 3 | O4: Instant Food | P4: Reorder Required | Q4: 78 | R4: 120 | S4: 744 | T4: 360 | AE4: 46054 | AF4: =SUM('Stok Awal'!B:B) -> 124508 | AG4: =SUMIFS(Barang_Masuk!F:F,Barang_Masuk!B:B,">="&DATE(2026,1,1),Barang_Masuk!B:B,"<"&DATE(2026,2,1)) -> 21260 | AH4: =SUMIFS(Barang_Keluar!F:F,Barang_Keluar!B:B,">="&DATE(2026,1,1),Barang_Keluar!B:B,"<"&DATE(2026,2,1)) -> 10231 | AI4: =AI3+AG4-AH4 -> 146566
A5: BEV003 | B5: =VLOOKUP(current_stock[[#This Row],[Item Code]],master_barang[],2,FALSE) -> Sosro Beverage Variant 3 | C5: =VLOOKUP(current_stock[[#This Row],[Item Code]],master_barang[],3,FALSE) -> Beverage | D5: =VLOOKUP(current_stock[[#This Row],[Item Code]],stok_awal[],2,FALSE) -> 140 | E5: =SUMIF(Barang_Masuk!D:D,A5,Barang_Masuk!F:F) -> 500 | F5: =SUMIF(Barang_Keluar!D:D,A5,Barang_Keluar!F:F) -> 384 | G5: =current_stock[[#This Row],[Stock Awal]]+current_stock[[#This Row],[Qty Received]]-current_stock[[#This Row],[Qty Dispatched]] -> 256 | H5: =VLOOKUP(current_stock[[#This Row],[Item Code]],master_barang[],9,FALSE) -> 40 | I5: =VLOOKUP(current_stock[[#This Row],[Item Code]],master_barang[],11,FALSE) -> 20 | J5: =VLOOKUP(current_stock[[#This Row],[Item Code]],master_barang[],10,FALSE) -> 160 | K5: =IF(current_stock[[#This Row],[Qty Available]]<current_stock[[#This Row],[Re Order Point]],"Reorder Required",IF(current_stock[[#This Row],[Qty Available]]>current_stock[[#This Row],[Maximum Stock]],"Overstock","Safe Stock Level")) -> Overstock | M5: SNK010 | N5: Taro Snack Variant 10 | O5: Snack | P5: Safe Stock Level | Q5: 94 | R5: 60 | S5: 462 | T5: 420 | AE5: 46082 | AF5: =SUM('Stok Awal'!B:B) -> 124508 | AG5: =SUMIFS(Barang_Masuk!F:F,Barang_Masuk!B:B,">="&DATE(2026,1,1),Barang_Masuk!B:B,"<"&DATE(2026,2,1)) -> 21260 | AH5: =SUMIFS(Barang_Keluar!F:F,Barang_Keluar!B:B,">="&DATE(2026,1,1),Barang_Keluar!B:B,"<"&DATE(2026,2,1)) -> 10231 | AI5: =AI4+AG5-AH5 -> 157595
A6: BEV004 | B6: =VLOOKUP(current_stock[[#This Row],[Item Code]],master_barang[],2,FALSE) -> Aqua Beverage Variant 4 | C6: =VLOOKUP(current_stock[[#This Row],[Item Code]],master_barang[],3,FALSE) -> Beverage | D6: =VLOOKUP(current_stock[[#This Row],[Item Code]],stok_awal[],2,FALSE) -> 894 | E6: =SUMIF(Barang_Masuk!D:D,A6,Barang_Masuk!F:F) -> 460 | F6: =SUMIF(Barang_Keluar!D:D,A6,Barang_Keluar!F:F) -> 293 | G6: =current_stock[[#This Row],[Stock Awal]]+current_stock[[#This Row],[Qty Received]]-current_stock[[#This Row],[Qty Dispatched]] -> 1061 | H6: =VLOOKUP(current_stock[[#This Row],[Item Code]],master_barang[],9,FALSE) -> 180 | I6: =VLOOKUP(current_stock[[#This Row],[Item Code]],master_barang[],11,FALSE) -> 90 | J6: =VLOOKUP(current_stock[[#This Row],[Item Code]],master_barang[],10,FALSE) -> 900 | K6: =IF(current_stock[[#This Row],[Qty Available]]<current_stock[[#This Row],[Re Order Point]],"Reorder Required",IF(current_stock[[#This Row],[Qty Available]]>current_stock[[#This Row],[Maximum Stock]],"Overstock","Safe Stock Level")) -> Overstock | M6: DAR019 | N6: Ultra Milk Dairy Variant 19 | O6: Dairy | P6: Overstock | Q6: 133 | R6: 20 | S6: 281 | T6: 350 | AE6: 46113 | AF6: =SUM('Stok Awal'!B:B) -> 124508 | AG6: =SUMIFS(Barang_Masuk!F:F,Barang_Masuk!B:B,">="&DATE(2026,1,1),Barang_Masuk!B:B,"<"&DATE(2026,2,1)) -> 21260 | AH6: =SUMIFS(Barang_Keluar!F:F,Barang_Keluar!B:B,">="&DATE(2026,1,1),Barang_Keluar!B:B,"<"&DATE(2026,2,1)) -> 10231 | AI6: =AI5+AG6-AH6 -> 168624
A7: BEV005 | B7: =VLOOKUP(current_stock[[#This Row],[Item Code]],master_barang[],2,FALSE) -> Aqua Beverage Variant 5 | C7: =VLOOKUP(current_stock[[#This Row],[Item Code]],master_barang[],3,FALSE) -> Beverage | D7: =VLOOKUP(current_stock[[#This Row],[Item Code]],stok_awal[],2,FALSE) -> 174 | E7: =SUMIF(Barang_Masuk!D:D,A7,Barang_Masuk!F:F) -> 1080 | F7: =SUMIF(Barang_Keluar!D:D,A7,Barang_Keluar!F:F) -> 308 | G7: =current_stock[[#This Row],[Stock Awal]]+current_stock[[#This Row],[Qty Received]]-current_stock[[#This Row],[Qty Dispatched]] -> 946 | H7: =VLOOKUP(current_stock[[#This Row],[Item Code]],master_barang[],9,FALSE) -> 80 | I7: =VLOOKUP(current_stock[[#This Row],[Item Code]],master_barang[],11,FALSE) -> 40 | J7: =VLOOKUP(current_stock[[#This Row],[Item Code]],master_barang[],10,FALSE) -> 320 | K7: =IF(current_stock[[#This Row],[Qty Available]]<current_stock[[#This Row],[Re Order Point]],"Reorder Required",IF(current_stock[[#This Row],[Qty Available]]>current_stock[[#This Row],[Maximum Stock]],"Overstock","Safe Stock Level")) -> Overstock | M7: PER015 | N7: Sunsilk Personal Care Variant 15 | O7: Personal Care | P7: Safe Stock Level | Q7: 193 | R7: 60 | S7: 325 | T7: 290 | AE7: 46143 | AF7: =SUM('Stok Awal'!B:B) -> 124508 | AG7: =SUMIFS(Barang_Masuk!F:F,Barang_Masuk!B:B,">="&DATE(2026,1,1),Barang_Masuk!B:B,"<"&DATE(2026,2,1)) -> 21260 | AH7: =SUMIFS(Barang_Keluar!F:F,Barang_Keluar!B:B,">="&DATE(2026,1,1),Barang_Keluar!B:B,"<"&DATE(2026,2,1)) -> 10231 | AI7: =AI6+AG7-AH7 -> 179653
A8: BEV006 | B8: =VLOOKUP(current_stock[[#This Row],[Item Code]],master_barang[],2,FALSE) -> Pocari Beverage Variant 6 | C8: =VLOOKUP(current_stock[[#This Row],[Item Code]],master_barang[],3,FALSE) -> Beverage | D8: =VLOOKUP(current_stock[[#This Row],[Item Code]],stok_awal[],2,FALSE) -> 369 | E8: =SUMIF(Barang_Masuk!D:D,A8,Barang_Masuk!F:F) -> 290 | F8: =SUMIF(Barang_Keluar!D:D,A8,Barang_Keluar!F:F) -> 243 | G8: =current_stock[[#This Row],[Stock Awal]]+current_stock[[#This Row],[Qty Received]]-current_stock[[#This Row],[Qty Dispatched]] -> 416 | H8: =VLOOKUP(current_stock[[#This Row],[Item Code]],master_barang[],9,FALSE) -> 100 | I8: =VLOOKUP(current_stock[[#This Row],[Item Code]],master_barang[],11,FALSE) -> 50 | J8: =VLOOKUP(current_stock[[#This Row],[Item Code]],master_barang[],10,FALSE) -> 500 | K8: =IF(current_stock[[#This Row],[Qty Available]]<current_stock[[#This Row],[Re Order Point]],"Reorder Required",IF(current_stock[[#This Row],[Qty Available]]>current_stock[[#This Row],[Maximum Stock]],"Overstock","Safe Stock Level")) -> Safe Stock Level | M8: BAB008 | N8: Zwitsal Baby Care Variant 8 | O8: Baby Care | P8: Safe Stock Level | Q8: 222 | R8: 200 | S8: 403 | T8: 80 | AE8: 46174 | AF8: =SUM('Stok Awal'!B:B) -> 124508 | AG8: =SUMIFS(Barang_Masuk!F:F,Barang_Masuk!B:B,">="&DATE(2026,1,1),Barang_Masuk!B:B,"<"&DATE(2026,2,1)) -> 21260 | AH8: =SUMIFS(Barang_Keluar!F:F,Barang_Keluar!B:B,">="&DATE(2026,1,1),Barang_Keluar!B:B,"<"&DATE(2026,2,1)) -> 10231 | AI8: =AI7+AG8-AH8 -> 190682
A9: BEV007 | B9: =VLOOKUP(current_stock[[#This Row],[Item Code]],master_barang[],2,FALSE) -> Sosro Beverage Variant 7 | C9: =VLOOKUP(current_stock[[#This Row],[Item Code]],master_barang[],3,FALSE) -> Beverage | D9: =VLOOKUP(current_stock[[#This Row],[Item Code]],stok_awal[],2,FALSE) -> 1802 | E9: =SUMIF(Barang_Masuk!D:D,A9,Barang_Masuk!F:F) -> 400 | F9: =SUMIF(Barang_Keluar!D:D,A9,Barang_Keluar!F:F) -> 94 | G9: =current_stock[[#This Row],[Stock Awal]]+current_stock[[#This Row],[Qty Received]]-current_stock[[#This Row],[Qty Dispatched]] -> 2108 | H9: =VLOOKUP(current_stock[[#This Row],[Item Code]],master_barang[],9,FALSE) -> 500 | I9: =VLOOKUP(current_stock[[#This Row],[Item Code]],master_barang[],11,FALSE) -> 250 | J9: =VLOOKUP(current_stock[[#This Row],[Item Code]],master_barang[],10,FALSE) -> 2000 | K9: =IF(current_stock[[#This Row],[Qty Available]]<current_stock[[#This Row],[Re Order Point]],"Reorder Required",IF(current_stock[[#This Row],[Qty Available]]>current_stock[[#This Row],[Maximum Stock]],"Overstock","Safe Stock Level")) -> Overstock | M9: BEV003 | N9: Sosro Beverage Variant 3 | O9: Beverage | P9: Overstock | Q9: 256 | R9: 40 | S9: 384 | T9: 500
A10: BEV008 | B10: =VLOOKUP(current_stock[[#This Row],[Item Code]],master_barang[],2,FALSE) -> Aqua Beverage Variant 8 | C10: =VLOOKUP(current_stock[[#This Row],[Item Code]],master_barang[],3,FALSE) -> Beverage | D10: =VLOOKUP(current_stock[[#This Row],[Item Code]],stok_awal[],2,FALSE) -> 46 | E10: =SUMIF(Barang_Masuk!D:D,A10,Barang_Masuk!F:F) -> 690 | F10: =SUMIF(Barang_Keluar!D:D,A10,Barang_Keluar!F:F) -> 216 | G10: =current_stock[[#This Row],[Stock Awal]]+current_stock[[#This Row],[Qty Received]]-current_stock[[#This Row],[Qty Dispatched]] -> 520 | H10: =VLOOKUP(current_stock[[#This Row],[Item Code]],master_barang[],9,FALSE) -> 20 | I10: =VLOOKUP(current_stock[[#This Row],[Item Code]],master_barang[],11,FALSE) -> 10 | J10: =VLOOKUP(current_stock[[#This Row],[Item Code]],master_barang[],10,FALSE) -> 100 | K10: =IF(current_stock[[#This Row],[Qty Available]]<current_stock[[#This Row],[Re Order Point]],"Reorder Required",IF(current_stock[[#This Row],[Qty Available]]>current_stock[[#This Row],[Maximum Stock]],"Overstock","Safe Stock Level")) -> Overstock | M10: BEV032 | N10: Aqua Beverage Variant 32 | O10: Beverage | P10: Safe Stock Level | Q10: 276 | R10: 100 | S10: 386 | T10: 390
A11: BEV009 | B11: =VLOOKUP(current_stock[[#This Row],[Item Code]],master_barang[],2,FALSE) -> Aqua Beverage Variant 9 | C11: =VLOOKUP(current_stock[[#This Row],[Item Code]],master_barang[],3,FALSE) -> Beverage | D11: =VLOOKUP(current_stock[[#This Row],[Item Code]],stok_awal[],2,FALSE) -> 361 | E11: =SUMIF(Barang_Masuk!D:D,A11,Barang_Masuk!F:F) -> 370 | F11: =SUMIF(Barang_Keluar!D:D,A11,Barang_Keluar!F:F) -> 394 | G11: =current_stock[[#This Row],[Stock Awal]]+current_stock[[#This Row],[Qty Received]]-current_stock[[#This Row],[Qty Dispatched]] -> 337 | H11: =VLOOKUP(current_stock[[#This Row],[Item Code]],master_barang[],9,FALSE) -> 100 | I11: =VLOOKUP(current_stock[[#This Row],[Item Code]],master_barang[],11,FALSE) -> 50 | J11: =VLOOKUP(current_stock[[#This Row],[Item Code]],master_barang[],10,FALSE) -> 400 | K11: =IF(current_stock[[#This Row],[Qty Available]]<current_stock[[#This Row],[Re Order Point]],"Reorder Required",IF(current_stock[[#This Row],[Qty Available]]>current_stock[[#This Row],[Maximum Stock]],"Overstock","Safe Stock Level")) -> Safe Stock Level | M11: INS025 | N11: Indomie Instant Food Variant 25 | O11: Instant Food | P11: Safe Stock Level | Q11: 277 | R11: 60 | S11: 210 | T11: 320
A12: BEV010 | B12: =VLOOKUP(current_stock[[#This Row],[Item Code]],master_barang[],2,FALSE) -> Coca Cola Beverage Variant 10 | C12: =VLOOKUP(current_stock[[#This Row],[Item Code]],master_barang[],3,FALSE) -> Beverage | D12: =VLOOKUP(current_stock[[#This Row],[Item Code]],stok_awal[],2,FALSE) -> 567 | E12: =SUMIF(Barang_Masuk!D:D,A12,Barang_Masuk!F:F) -> 830 | F12: =SUMIF(Barang_Keluar!D:D,A12,Barang_Keluar!F:F) -> 315 | G12: =current_stock[[#This Row],[Stock Awal]]+current_stock[[#This Row],[Qty Received]]-current_stock[[#This Row],[Qty Dispatched]] -> 1082 | H12: =VLOOKUP(current_stock[[#This Row],[Item Code]],master_barang[],9,FALSE) -> 180 | I12: =VLOOKUP(current_stock[[#This Row],[Item Code]],master_barang[],11,FALSE) -> 90 | J12: =VLOOKUP(current_stock[[#This Row],[Item Code]],master_barang[],10,FALSE) -> 1080 | K12: =IF(current_stock[[#This Row],[Qty Available]]<current_stock[[#This Row],[Re Order Point]],"Reorder Required",IF(current_stock[[#This Row],[Qty Available]]>current_stock[[#This Row],[Maximum Stock]],"Overstock","Safe Stock Level")) -> Overstock | M12: SNK030 | N12: Qtela Snack Variant 30 | O12: Snack | P12: Safe Stock Level | Q12: 278 | R12: 100 | S12: 288 | T12: 270
A13: BEV011 | B13: =VLOOKUP(current_stock[[#This Row],[Item Code]],master_barang[],2,FALSE) -> Pocari Beverage Variant 11 | C13: =VLOOKUP(current_stock[[#This Row],[Item Code]],master_barang[],3,FALSE) -> Beverage | D13: =VLOOKUP(current_stock[[#This Row],[Item Code]],stok_awal[],2,FALSE) -> 626 | E13: =SUMIF(Barang_Masuk!D:D,A13,Barang_Masuk!F:F) -> 440 | F13: =SUMIF(Barang_Keluar!D:D,A13,Barang_Keluar!F:F) -> 224 | G13: =current_stock[[#This Row],[Stock Awal]]+current_stock[[#This Row],[Qty Received]]-current_stock[[#This Row],[Qty Dispatched]] -> 842 | H13: =VLOOKUP(current_stock[[#This Row],[Item Code]],master_barang[],9,FALSE) -> 150 | I13: =VLOOKUP(current_stock[[#This Row],[Item Code]],master_barang[],11,FALSE) -> 75 | J13: =VLOOKUP(current_stock[[#This Row],[Item Code]],master_barang[],10,FALSE) -> 900 | K13: =IF(current_stock[[#This Row],[Qty Available]]<current_stock[[#This Row],[Re Order Point]],"Reorder Required",IF(current_stock[[#This Row],[Qty Available]]>current_stock[[#This Row],[Maximum Stock]],"Overstock","Safe Stock Level")) -> Safe Stock Level | M13: BEV012 | N13: Pocari Beverage Variant 12 | O13: Beverage | P13: Overstock | Q13: 292 | R13: 40 | S13: 371 | T13: 470
A14: BEV012 | B14: =VLOOKUP(current_stock[[#This Row],[Item Code]],master_barang[],2,FALSE) -> Pocari Beverage Variant 12 | C14: =VLOOKUP(current_stock[[#This Row],[Item Code]],master_barang[],3,FALSE) -> Beverage | D14: =VLOOKUP(current_stock[[#This Row],[Item Code]],stok_awal[],2,FALSE) -> 193 | E14: =SUMIF(Barang_Masuk!D:D,A14,Barang_Masuk!F:F) -> 470 | F14: =SUMIF(Barang_Keluar!D:D,A14,Barang_Keluar!F:F) -> 371 | G14: =current_stock[[#This Row],[Stock Awal]]+current_stock[[#This Row],[Qty Received]]-current_stock[[#This Row],[Qty Dispatched]] -> 292 | H14: =VLOOKUP(current_stock[[#This Row],[Item Code]],master_barang[],9,FALSE) -> 40 | I14: =VLOOKUP(current_stock[[#This Row],[Item Code]],master_barang[],11,FALSE) -> 20 | J14: =VLOOKUP(current_stock[[#This Row],[Item Code]],master_barang[],10,FALSE) -> 160 | K14: =IF(current_stock[[#This Row],[Qty Available]]<current_stock[[#This Row],[Re Order Point]],"Reorder Required",IF(current_stock[[#This Row],[Qty Available]]>current_stock[[#This Row],[Maximum Stock]],"Overstock","Safe Stock Level")) -> Overstock | M14: PER002 | N14: Lifebuoy Personal Care Variant 2 | O14: Personal Care | P14: Overstock | Q14: 304 | R14: 20 | S14: 239 | T14: 470
A15: BEV013 | B15: =VLOOKUP(current_stock[[#This Row],[Item Code]],master_barang[],2,FALSE) -> Sosro Beverage Variant 13 | C15: =VLOOKUP(current_stock[[#This Row],[Item Code]],master_barang[],3,FALSE) -> Beverage | D15: =VLOOKUP(current_stock[[#This Row],[Item Code]],stok_awal[],2,FALSE) -> 529 | E15: =SUMIF(Barang_Masuk!D:D,A15,Barang_Masuk!F:F) -> 590 | F15: =SUMIF(Barang_Keluar!D:D,A15,Barang_Keluar!F:F) -> 231 | G15: =current_stock[[#This Row],[Stock Awal]]+current_stock[[#This Row],[Qty Received]]-current_stock[[#This Row],[Qty Dispatched]] -> 888 | H15: =VLOOKUP(current_stock[[#This Row],[Item Code]],master_barang[],9,FALSE) -> 200 | I15: =VLOOKUP(current_stock[[#This Row],[Item Code]],master_barang[],11,FALSE) -> 100 | J15: =VLOOKUP(current_stock[[#This Row],[Item Code]],master_barang[],10,FALSE) -> 800 | K15: =IF(current_stock[[#This Row],[Qty Available]]<current_stock[[#This Row],[Re Order Point]],"Reorder Required",IF(current_stock[[#This Row],[Qty Available]]>current_stock[[#This Row],[Maximum Stock]],"Overstock","Safe Stock Level")) -> Overstock | M15: SNK023 | N15: Taro Snack Variant 23 | O15: Snack | P15: Overstock | Q15: 321 | R15: 60 | S15: 372 | T15: 540
A16: BEV014 | B16: =VLOOKUP(current_stock[[#This Row],[Item Code]],master_barang[],2,FALSE) -> Coca Cola Beverage Variant 14 | C16: =VLOOKUP(current_stock[[#This Row],[Item Code]],master_barang[],3,FALSE) -> Beverage | D16: =VLOOKUP(current_stock[[#This Row],[Item Code]],stok_awal[],2,FALSE) -> 1293 | E16: =SUMIF(Barang_Masuk!D:D,A16,Barang_Masuk!F:F) -> 770 | F16: =SUMIF(Barang_Keluar!D:D,A16,Barang_Keluar!F:F) -> 317 | G16: =current_stock[[#This Row],[Stock Awal]]+current_stock[[#This Row],[Qty Received]]-current_stock[[#This Row],[Qty Dispatched]] -> 1746 | H16: =VLOOKUP(current_stock[[#This Row],[Item Code]],master_barang[],9,FALSE) -> 400 | I16: =VLOOKUP(current_stock[[#This Row],[Item Code]],master_barang[],11,FALSE) -> 200 | J16: =VLOOKUP(current_stock[[#This Row],[Item Code]],master_barang[],10,FALSE) -> 2400 | K16: =IF(current_stock[[#This Row],[Qty Available]]<current_stock[[#This Row],[Re Order Point]],"Reorder Required",IF(current_stock[[#This Row],[Qty Available]]>current_stock[[#This Row],[Maximum Stock]],"Overstock","Safe Stock Level")) -> Safe Stock Level | M16: BEV035 | N16: Sosro Beverage Variant 35 | O16: Beverage | P16: Overstock | Q16: 332 | R16: 80 | S16: 386 | T16: 340
A17: BEV015 | B17: =VLOOKUP(current_stock[[#This Row],[Item Code]],master_barang[],2,FALSE) -> Aqua Beverage Variant 15 | C17: =VLOOKUP(current_stock[[#This Row],[Item Code]],master_barang[],3,FALSE) -> Beverage | D17: =VLOOKUP(current_stock[[#This Row],[Item Code]],stok_awal[],2,FALSE) -> 313 | E17: =SUMIF(Barang_Masuk!D:D,A17,Barang_Masuk!F:F) -> 940 | F17: =SUMIF(Barang_Keluar!D:D,A17,Barang_Keluar!F:F) -> 445 | G17: =current_stock[[#This Row],[Stock Awal]]+current_stock[[#This Row],[Qty Received]]-current_stock[[#This Row],[Qty Dispatched]] -> 808 | H17: =VLOOKUP(current_stock[[#This Row],[Item Code]],master_barang[],9,FALSE) -> 150 | I17: =VLOOKUP(current_stock[[#This Row],[Item Code]],master_barang[],11,FALSE) -> 75 | J17: =VLOOKUP(current_stock[[#This Row],[Item Code]],master_barang[],10,FALSE) -> 900 | K17: =IF(current_stock[[#This Row],[Qty Available]]<current_stock[[#This Row],[Re Order Point]],"Reorder Required",IF(current_stock[[#This Row],[Qty Available]]>current_stock[[#This Row],[Maximum Stock]],"Overstock","Safe Stock Level")) -> Safe Stock Level | M17: BEV039 | N17: Pocari Beverage Variant 39 | O17: Beverage | P17: Safe Stock Level | Q17: 333 | R17: 60 | S17: 332 | T17: 480
A18: BEV016 | B18: =VLOOKUP(current_stock[[#This Row],[Item Code]],master_barang[],2,FALSE) -> Sosro Beverage Variant 16 | C18: =VLOOKUP(current_stock[[#This Row],[Item Code]],master_barang[],3,FALSE) -> Beverage | D18: =VLOOKUP(current_stock[[#This Row],[Item Code]],stok_awal[],2,FALSE) -> 745 | E18: =SUMIF(Barang_Masuk!D:D,A18,Barang_Masuk!F:F) -> 430 | F18: =SUMIF(Barang_Keluar!D:D,A18,Barang_Keluar!F:F) -> 409 | G18: =current_stock[[#This Row],[Stock Awal]]+current_stock[[#This Row],[Qty Received]]-current_stock[[#This Row],[Qty Dispatched]] -> 766 | H18: =VLOOKUP(current_stock[[#This Row],[Item Code]],master_barang[],9,FALSE) -> 180 | I18: =VLOOKUP(current_stock[[#This Row],[Item Code]],master_barang[],11,FALSE) -> 90 | J18: =VLOOKUP(current_stock[[#This Row],[Item Code]],master_barang[],10,FALSE) -> 1080 | K18: =IF(current_stock[[#This Row],[Qty Available]]<current_stock[[#This Row],[Re Order Point]],"Reorder Required",IF(current_stock[[#This Row],[Qty Available]]>current_stock[[#This Row],[Maximum Stock]],"Overstock","Safe Stock Level")) -> Safe Stock Level | M18: BAB002 | N18: Zwitsal Baby Care Variant 2 | O18: Baby Care | P18: Safe Stock Level | Q18: 333 | R18: 120 | S18: 411 | T18: 490
A19: BEV017 | B19: =VLOOKUP(current_stock[[#This Row],[Item Code]],master_barang[],2,FALSE) -> Aqua Beverage Variant 17 | C19: =VLOOKUP(current_stock[[#This Row],[Item Code]],master_barang[],3,FALSE) -> Beverage | D19: =VLOOKUP(current_stock[[#This Row],[Item Code]],stok_awal[],2,FALSE) -> 286 | E19: =SUMIF(Barang_Masuk!D:D,A19,Barang_Masuk!F:F) -> 770 | F19: =SUMIF(Barang_Keluar!D:D,A19,Barang_Keluar!F:F) -> 335 | G19: =current_stock[[#This Row],[Stock Awal]]+current_stock[[#This Row],[Qty Received]]-current_stock[[#This Row],[Qty Dispatched]] -> 721 | H19: =VLOOKUP(current_stock[[#This Row],[Item Code]],master_barang[],9,FALSE) -> 120 | I19: =VLOOKUP(current_stock[[#This Row],[Item Code]],master_barang[],11,FALSE) -> 60 | J19: =VLOOKUP(current_stock[[#This Row],[Item Code]],master_barang[],10,FALSE) -> 600 | K19: =IF(current_stock[[#This Row],[Qty Available]]<current_stock[[#This Row],[Re Order Point]],"Reorder Required",IF(current_stock[[#This Row],[Qty Available]]>current_stock[[#This Row],[Maximum Stock]],"Overstock","Safe Stock Level")) -> Overstock | M19: BEV009 | N19: Aqua Beverage Variant 9 | O19: Beverage | P19: Safe Stock Level | Q19: 337 | R19: 100 | S19: 394 | T19: 370
A20: BEV018 | B20: =VLOOKUP(current_stock[[#This Row],[Item Code]],master_barang[],2,FALSE) -> Sosro Beverage Variant 18 | C20: =VLOOKUP(current_stock[[#This Row],[Item Code]],master_barang[],3,FALSE) -> Beverage | D20: =VLOOKUP(current_stock[[#This Row],[Item Code]],stok_awal[],2,FALSE) -> 2062 | E20: =SUMIF(Barang_Masuk!D:D,A20,Barang_Masuk!F:F) -> 790 | F20: =SUMIF(Barang_Keluar!D:D,A20,Barang_Keluar!F:F) -> 339 | G20: =current_stock[[#This Row],[Stock Awal]]+current_stock[[#This Row],[Qty Received]]-current_stock[[#This Row],[Qty Dispatched]] -> 2513 | H20: =VLOOKUP(current_stock[[#This Row],[Item Code]],master_barang[],9,FALSE) -> 500 | I20: =VLOOKUP(current_stock[[#This Row],[Item Code]],master_barang[],11,FALSE) -> 250 | J20: =VLOOKUP(current_stock[[#This Row],[Item Code]],master_barang[],10,FALSE) -> 2000 | K20: =IF(current_stock[[#This Row],[Qty Available]]<current_stock[[#This Row],[Re Order Point]],"Reorder Required",IF(current_stock[[#This Row],[Qty Available]]>current_stock[[#This Row],[Maximum Stock]],"Overstock","Safe Stock Level")) -> Overstock | M20: BAB009 | N20: MamyPoko Baby Care Variant 9 | O20: Baby Care | P20: Safe Stock Level | Q20: 338 | R20: 120 | S20: 232 | T20: 220
... A202: BAB020 | B202: =VLOOKUP(current_stock[[#This Row],[Item Code]],master_barang[],2,FALSE) -> Zwitsal Baby Care Variant 20 | C202: =VLOOKUP(current_stock[[#This Row],[Item Code]],master_barang[],3,FALSE) -> Baby Care | D202: =VLOOKUP(current_stock[[#This Row],[Item Code]],stok_awal[],2,FALSE) -> 1614 | E202: =SUMIF(Barang_Masuk!D:D,A202,Barang_Masuk!F:F) -> 620 | F202: =SUMIF(Barang_Keluar!D:D,A202,Barang_Keluar!F:F) -> 431 | G202: =current_stock[[#This Row],[Stock Awal]]+current_stock[[#This Row],[Qty Received]]-current_stock[[#This Row],[Qty Dispatched]] -> 1803 | H202: =VLOOKUP(current_stock[[#This Row],[Item Code]],master_barang[],9,FALSE) -> 400 | I202: =VLOOKUP(current_stock[[#This Row],[Item Code]],master_barang[],11,FALSE) -> 200 | J202: =VLOOKUP(current_stock[[#This Row],[Item Code]],master_barang[],10,FALSE) -> 1600 | K202: =IF(current_stock[[#This Row],[Qty Available]]<current_stock[[#This Row],[Re Order Point]],"Reorder Required",IF(current_stock[[#This Row],[Qty Available]]>current_stock[[#This Row],[Maximum Stock]],"Overstock","Safe Stock Level")) -> Overstock | M202: SNK031 | N202: Taro Snack Variant 31 | O202: Snack | P202: Overstock | Q202: 2808 | R202: 500 | S202: 261 | T202: 860
K203: Sum of % Avb Status

Sheet Data_Transaksi
A2: Reference Number | B2: Date | C2: Type | D2: Item Code | E2: Item Name | F2: Quantity | G2: Unit | H2: Supplier/Customer | I2: Helper
A3: GR202600001 | B3: =IF(LEFT(tbl_transaction[[#This Row],[Reference Number]],2)="GR",VLOOKUP(tbl_transaction[[#This Row],[Reference Number]],barang_masuk[],2,FALSE),IF(LEFT(tbl_transaction[[#This Row],[Reference Number]],2)="DO",VLOOKUP(tbl_transaction[[#This Row],[Reference Number]],barang_keluar[],2,FALSE),"")) -> 46088 | C3: =IF(LEFT(A3,2)="GR","Inbound",IF(LEFT(A3,2)="DO","Outbound","")) -> Inbound | D3: =IF(tbl_transaction[[#This Row],[Type]]="Inbound",VLOOKUP(tbl_transaction[[#This Row],[Reference Number]],barang_masuk[],4,FALSE),IF(tbl_transaction[[#This Row],[Type]]="Outbound",VLOOKUP(tbl_transaction[[#This Row],[Reference Number]],barang_keluar[],4,FALSE),"")) -> BAB018 | E3: =IF(tbl_transaction[[#This Row],[Type]]="Inbound",VLOOKUP(tbl_transaction[[#This Row],[Reference Number]],barang_masuk[],5,FALSE),IF(tbl_transaction[[#This Row],[Type]]="Outbound",VLOOKUP(tbl_transaction[[#This Row],[Reference Number]],barang_keluar[],5,FALSE),"")) -> MamyPoko Baby Care Variant 18 | F3: =IF(tbl_transaction[[#This Row],[Type]]="Inbound",VLOOKUP(tbl_transaction[[#This Row],[Reference Number]],barang_masuk[],6,FALSE),IF(tbl_transaction[[#This Row],[Type]]="Outbound",VLOOKUP(tbl_transaction[[#This Row],[Reference Number]],barang_keluar[],6,FALSE),"")) -> 20 | G3: =IF(tbl_transaction[[#This Row],[Type]]="Inbound",VLOOKUP(tbl_transaction[[#This Row],[Reference Number]],barang_masuk[],7,FALSE),IF(tbl_transaction[[#This Row],[Type]]="Outbound",VLOOKUP(tbl_transaction[[#This Row],[Reference Number]],barang_keluar[],7,FALSE),"")) -> Pack | H3: =IF(tbl_transaction[[#This Row],[Type]]="Inbound",VLOOKUP(tbl_transaction[[#This Row],[Reference Number]],barang_masuk[],3,FALSE),IF(tbl_transaction[[#This Row],[Type]]="Outbound",VLOOKUP(tbl_transaction[[#This Row],[Reference Number]],barang_keluar[],3,FALSE),"")) -> PT Supplier 34 | I3: =IF(D3='Kartu Stok'!$B$2,COUNTIF($D$3:D3,'Kartu Stok'!$B$2),"") -> 1
A4: GR202600002 | B4: =IF(LEFT(tbl_transaction[[#This Row],[Reference Number]],2)="GR",VLOOKUP(tbl_transaction[[#This Row],[Reference Number]],barang_masuk[],2,FALSE),IF(LEFT(tbl_transaction[[#This Row],[Reference Number]],2)="DO",VLOOKUP(tbl_transaction[[#This Row],[Reference Number]],barang_keluar[],2,FALSE),"")) -> 46024 | C4: =IF(LEFT(A4,2)="GR","Inbound",IF(LEFT(A4,2)="DO","Outbound","")) -> Inbound | D4: =IF(tbl_transaction[[#This Row],[Type]]="Inbound",VLOOKUP(tbl_transaction[[#This Row],[Reference Number]],barang_masuk[],4,FALSE),IF(tbl_transaction[[#This Row],[Type]]="Outbound",VLOOKUP(tbl_transaction[[#This Row],[Reference Number]],barang_keluar[],4,FALSE),"")) -> BAB005 | E4: =IF(tbl_transaction[[#This Row],[Type]]="Inbound",VLOOKUP(tbl_transaction[[#This Row],[Reference Number]],barang_masuk[],5,FALSE),IF(tbl_transaction[[#This Row],[Type]]="Outbound",VLOOKUP(tbl_transaction[[#This Row],[Reference Number]],barang_keluar[],5,FALSE),"")) -> Zwitsal Baby Care Variant 5 | F4: =IF(tbl_transaction[[#This Row],[Type]]="Inbound",VLOOKUP(tbl_transaction[[#This Row],[Reference Number]],barang_masuk[],6,FALSE),IF(tbl_transaction[[#This Row],[Type]]="Outbound",VLOOKUP(tbl_transaction[[#This Row],[Reference Number]],barang_keluar[],6,FALSE),"")) -> 150 | G4: =IF(tbl_transaction[[#This Row],[Type]]="Inbound",VLOOKUP(tbl_transaction[[#This Row],[Reference Number]],barang_masuk[],7,FALSE),IF(tbl_transaction[[#This Row],[Type]]="Outbound",VLOOKUP(tbl_transaction[[#This Row],[Reference Number]],barang_keluar[],7,FALSE),"")) -> Pack | H4: =IF(tbl_transaction[[#This Row],[Type]]="Inbound",VLOOKUP(tbl_transaction[[#This Row],[Reference Number]],barang_masuk[],3,FALSE),IF(tbl_transaction[[#This Row],[Type]]="Outbound",VLOOKUP(tbl_transaction[[#This Row],[Reference Number]],barang_keluar[],3,FALSE),"")) -> PT Supplier 18 | I4: =IF(D4='Kartu Stok'!$B$2,COUNTIF($D$3:D4,'Kartu Stok'!$B$2),"")
A5: GR202600003 | B5: =IF(LEFT(tbl_transaction[[#This Row],[Reference Number]],2)="GR",VLOOKUP(tbl_transaction[[#This Row],[Reference Number]],barang_masuk[],2,FALSE),IF(LEFT(tbl_transaction[[#This Row],[Reference Number]],2)="DO",VLOOKUP(tbl_transaction[[#This Row],[Reference Number]],barang_keluar[],2,FALSE),"")) -> 46051 | C5: =IF(LEFT(A5,2)="GR","Inbound",IF(LEFT(A5,2)="DO","Outbound","")) -> Inbound | D5: =IF(tbl_transaction[[#This Row],[Type]]="Inbound",VLOOKUP(tbl_transaction[[#This Row],[Reference Number]],barang_masuk[],4,FALSE),IF(tbl_transaction[[#This Row],[Type]]="Outbound",VLOOKUP(tbl_transaction[[#This Row],[Reference Number]],barang_keluar[],4,FALSE),"")) -> BAB012 | E5: =IF(tbl_transaction[[#This Row],[Type]]="Inbound",VLOOKUP(tbl_transaction[[#This Row],[Reference Number]],barang_masuk[],5,FALSE),IF(tbl_transaction[[#This Row],[Type]]="Outbound",VLOOKUP(tbl_transaction[[#This Row],[Reference Number]],barang_keluar[],5,FALSE),"")) -> MamyPoko Baby Care Variant 12 | F5: =IF(tbl_transaction[[#This Row],[Type]]="Inbound",VLOOKUP(tbl_transaction[[#This Row],[Reference Number]],barang_masuk[],6,FALSE),IF(tbl_transaction[[#This Row],[Type]]="Outbound",VLOOKUP(tbl_transaction[[#This Row],[Reference Number]],barang_keluar[],6,FALSE),"")) -> 120 | G5: =IF(tbl_transaction[[#This Row],[Type]]="Inbound",VLOOKUP(tbl_transaction[[#This Row],[Reference Number]],barang_masuk[],7,FALSE),IF(tbl_transaction[[#This Row],[Type]]="Outbound",VLOOKUP(tbl_transaction[[#This Row],[Reference Number]],barang_keluar[],7,FALSE),"")) -> Pack | H5: =IF(tbl_transaction[[#This Row],[Type]]="Inbound",VLOOKUP(tbl_transaction[[#This Row],[Reference Number]],barang_masuk[],3,FALSE),IF(tbl_transaction[[#This Row],[Type]]="Outbound",VLOOKUP(tbl_transaction[[#This Row],[Reference Number]],barang_keluar[],3,FALSE),"")) -> PT Supplier 08 | I5: =IF(D5='Kartu Stok'!$B$2,COUNTIF($D$3:D5,'Kartu Stok'!$B$2),"")
A6: GR202600004 | B6: =IF(LEFT(tbl_transaction[[#This Row],[Reference Number]],2)="GR",VLOOKUP(tbl_transaction[[#This Row],[Reference Number]],barang_masuk[],2,FALSE),IF(LEFT(tbl_transaction[[#This Row],[Reference Number]],2)="DO",VLOOKUP(tbl_transaction[[#This Row],[Reference Number]],barang_keluar[],2,FALSE),"")) -> 46099 | C6: =IF(LEFT(A6,2)="GR","Inbound",IF(LEFT(A6,2)="DO","Outbound","")) -> Inbound | D6: =IF(tbl_transaction[[#This Row],[Type]]="Inbound",VLOOKUP(tbl_transaction[[#This Row],[Reference Number]],barang_masuk[],4,FALSE),IF(tbl_transaction[[#This Row],[Type]]="Outbound",VLOOKUP(tbl_transaction[[#This Row],[Reference Number]],barang_keluar[],4,FALSE),"")) -> BEV034 | E6: =IF(tbl_transaction[[#This Row],[Type]]="Inbound",VLOOKUP(tbl_transaction[[#This Row],[Reference Number]],barang_masuk[],5,FALSE),IF(tbl_transaction[[#This Row],[Type]]="Outbound",VLOOKUP(tbl_transaction[[#This Row],[Reference Number]],barang_keluar[],5,FALSE),"")) -> Coca Cola Beverage Variant 34 | F6: =IF(tbl_transaction[[#This Row],[Type]]="Inbound",VLOOKUP(tbl_transaction[[#This Row],[Reference Number]],barang_masuk[],6,FALSE),IF(tbl_transaction[[#This Row],[Type]]="Outbound",VLOOKUP(tbl_transaction[[#This Row],[Reference Number]],barang_keluar[],6,FALSE),"")) -> 20 | G6: =IF(tbl_transaction[[#This Row],[Type]]="Inbound",VLOOKUP(tbl_transaction[[#This Row],[Reference Number]],barang_masuk[],7,FALSE),IF(tbl_transaction[[#This Row],[Type]]="Outbound",VLOOKUP(tbl_transaction[[#This Row],[Reference Number]],barang_keluar[],7,FALSE),"")) -> Bottle | H6: =IF(tbl_transaction[[#This Row],[Type]]="Inbound",VLOOKUP(tbl_transaction[[#This Row],[Reference Number]],barang_masuk[],3,FALSE),IF(tbl_transaction[[#This Row],[Type]]="Outbound",VLOOKUP(tbl_transaction[[#This Row],[Reference Number]],barang_keluar[],3,FALSE),"")) -> PT Supplier 03 | I6: =IF(D6='Kartu Stok'!$B$2,COUNTIF($D$3:D6,'Kartu Stok'!$B$2),"")
A7: GR202600005 | B7: =IF(LEFT(tbl_transaction[[#This Row],[Reference Number]],2)="GR",VLOOKUP(tbl_transaction[[#This Row],[Reference Number]],barang_masuk[],2,FALSE),IF(LEFT(tbl_transaction[[#This Row],[Reference Number]],2)="DO",VLOOKUP(tbl_transaction[[#This Row],[Reference Number]],barang_keluar[],2,FALSE),"")) -> 46096 | C7: =IF(LEFT(A7,2)="GR","Inbound",IF(LEFT(A7,2)="DO","Outbound","")) -> Inbound | D7: =IF(tbl_transaction[[#This Row],[Type]]="Inbound",VLOOKUP(tbl_transaction[[#This Row],[Reference Number]],barang_masuk[],4,FALSE),IF(tbl_transaction[[#This Row],[Type]]="Outbound",VLOOKUP(tbl_transaction[[#This Row],[Reference Number]],barang_keluar[],4,FALSE),"")) -> SNK034 | E7: =IF(tbl_transaction[[#This Row],[Type]]="Inbound",VLOOKUP(tbl_transaction[[#This Row],[Reference Number]],barang_masuk[],5,FALSE),IF(tbl_transaction[[#This Row],[Type]]="Outbound",VLOOKUP(tbl_transaction[[#This Row],[Reference Number]],barang_keluar[],5,FALSE),"")) -> Taro Snack Variant 34 | F7: =IF(tbl_transaction[[#This Row],[Type]]="Inbound",VLOOKUP(tbl_transaction[[#This Row],[Reference Number]],barang_masuk[],6,FALSE),IF(tbl_transaction[[#This Row],[Type]]="Outbound",VLOOKUP(tbl_transaction[[#This Row],[Reference Number]],barang_keluar[],6,FALSE),"")) -> 20 | G7: =IF(tbl_transaction[[#This Row],[Type]]="Inbound",VLOOKUP(tbl_transaction[[#This Row],[Reference Number]],barang_masuk[],7,FALSE),IF(tbl_transaction[[#This Row],[Type]]="Outbound",VLOOKUP(tbl_transaction[[#This Row],[Reference Number]],barang_keluar[],7,FALSE),"")) -> Pack | H7: =IF(tbl_transaction[[#This Row],[Type]]="Inbound",VLOOKUP(tbl_transaction[[#This Row],[Reference Number]],barang_masuk[],3,FALSE),IF(tbl_transaction[[#This Row],[Type]]="Outbound",VLOOKUP(tbl_transaction[[#This Row],[Reference Number]],barang_keluar[],3,FALSE),"")) -> PT Supplier 20 | I7: =IF(D7='Kartu Stok'!$B$2,COUNTIF($D$3:D7,'Kartu Stok'!$B$2),"")
A8: GR202600006 | B8: =IF(LEFT(tbl_transaction[[#This Row],[Reference Number]],2)="GR",VLOOKUP(tbl_transaction[[#This Row],[Reference Number]],barang_masuk[],2,FALSE),IF(LEFT(tbl_transaction[[#This Row],[Reference Number]],2)="DO",VLOOKUP(tbl_transaction[[#This Row],[Reference Number]],barang_keluar[],2,FALSE),"")) -> 46023 | C8: =IF(LEFT(A8,2)="GR","Inbound",IF(LEFT(A8,2)="DO","Outbound","")) -> Inbound | D8: =IF(tbl_transaction[[#This Row],[Type]]="Inbound",VLOOKUP(tbl_transaction[[#This Row],[Reference Number]],barang_masuk[],4,FALSE),IF(tbl_transaction[[#This Row],[Type]]="Outbound",VLOOKUP(tbl_transaction[[#This Row],[Reference Number]],barang_keluar[],4,FALSE),"")) -> PER007 | E8: =IF(tbl_transaction[[#This Row],[Type]]="Inbound",VLOOKUP(tbl_transaction[[#This Row],[Reference Number]],barang_masuk[],5,FALSE),IF(tbl_transaction[[#This Row],[Type]]="Outbound",VLOOKUP(tbl_transaction[[#This Row],[Reference Number]],barang_keluar[],5,FALSE),"")) -> Pepsodent Personal Care Variant 7 | F8: =IF(tbl_transaction[[#This Row],[Type]]="Inbound",VLOOKUP(tbl_transaction[[#This Row],[Reference Number]],barang_masuk[],6,FALSE),IF(tbl_transaction[[#This Row],[Type]]="Outbound",VLOOKUP(tbl_transaction[[#This Row],[Reference Number]],barang_keluar[],6,FALSE),"")) -> 20 | G8: =IF(tbl_transaction[[#This Row],[Type]]="Inbound",VLOOKUP(tbl_transaction[[#This Row],[Reference Number]],barang_masuk[],7,FALSE),IF(tbl_transaction[[#This Row],[Type]]="Outbound",VLOOKUP(tbl_transaction[[#This Row],[Reference Number]],barang_keluar[],7,FALSE),"")) -> Bottle | H8: =IF(tbl_transaction[[#This Row],[Type]]="Inbound",VLOOKUP(tbl_transaction[[#This Row],[Reference Number]],barang_masuk[],3,FALSE),IF(tbl_transaction[[#This Row],[Type]]="Outbound",VLOOKUP(tbl_transaction[[#This Row],[Reference Number]],barang_keluar[],3,FALSE),"")) -> PT Supplier 21 | I8: =IF(D8='Kartu Stok'!$B$2,COUNTIF($D$3:D8,'Kartu Stok'!$B$2),"")
A9: GR202600007 | B9: =IF(LEFT(tbl_transaction[[#This Row],[Reference Number]],2)="GR",VLOOKUP(tbl_transaction[[#This Row],[Reference Number]],barang_masuk[],2,FALSE),IF(LEFT(tbl_transaction[[#This Row],[Reference Number]],2)="DO",VLOOKUP(tbl_transaction[[#This Row],[Reference Number]],barang_keluar[],2,FALSE),"")) -> 46078 | C9: =IF(LEFT(A9,2)="GR","Inbound",IF(LEFT(A9,2)="DO","Outbound","")) -> Inbound | D9: =IF(tbl_transaction[[#This Row],[Type]]="Inbound",VLOOKUP(tbl_transaction[[#This Row],[Reference Number]],barang_masuk[],4,FALSE),IF(tbl_transaction[[#This Row],[Type]]="Outbound",VLOOKUP(tbl_transaction[[#This Row],[Reference Number]],barang_keluar[],4,FALSE),"")) -> SNK016 | E9: =IF(tbl_transaction[[#This Row],[Type]]="Inbound",VLOOKUP(tbl_transaction[[#This Row],[Reference Number]],barang_masuk[],5,FALSE),IF(tbl_transaction[[#This Row],[Type]]="Outbound",VLOOKUP(tbl_transaction[[#This Row],[Reference Number]],barang_keluar[],5,FALSE),"")) -> Qtela Snack Variant 16 | F9: =IF(tbl_transaction[[#This Row],[Type]]="Inbound",VLOOKUP(tbl_transaction[[#This Row],[Reference Number]],barang_masuk[],6,FALSE),IF(tbl_transaction[[#This Row],[Type]]="Outbound",VLOOKUP(tbl_transaction[[#This Row],[Reference Number]],barang_keluar[],6,FALSE),"")) -> 200 | G9: =IF(tbl_transaction[[#This Row],[Type]]="Inbound",VLOOKUP(tbl_transaction[[#This Row],[Reference Number]],barang_masuk[],7,FALSE),IF(tbl_transaction[[#This Row],[Type]]="Outbound",VLOOKUP(tbl_transaction[[#This Row],[Reference Number]],barang_keluar[],7,FALSE),"")) -> Pack | H9: =IF(tbl_transaction[[#This Row],[Type]]="Inbound",VLOOKUP(tbl_transaction[[#This Row],[Reference Number]],barang_masuk[],3,FALSE),IF(tbl_transaction[[#This Row],[Type]]="Outbound",VLOOKUP(tbl_transaction[[#This Row],[Reference Number]],barang_keluar[],3,FALSE),"")) -> PT Supplier 12 | I9: =IF(D9='Kartu Stok'!$B$2,COUNTIF($D$3:D9,'Kartu Stok'!$B$2),"")
A10: GR202600008 | B10: =IF(LEFT(tbl_transaction[[#This Row],[Reference Number]],2)="GR",VLOOKUP(tbl_transaction[[#This Row],[Reference Number]],barang_masuk[],2,FALSE),IF(LEFT(tbl_transaction[[#This Row],[Reference Number]],2)="DO",VLOOKUP(tbl_transaction[[#This Row],[Reference Number]],barang_keluar[],2,FALSE),"")) -> 46143 | C10: =IF(LEFT(A10,2)="GR","Inbound",IF(LEFT(A10,2)="DO","Outbound","")) -> Inbound | D10: =IF(tbl_transaction[[#This Row],[Type]]="Inbound",VLOOKUP(tbl_transaction[[#This Row],[Reference Number]],barang_masuk[],4,FALSE),IF(tbl_transaction[[#This Row],[Type]]="Outbound",VLOOKUP(tbl_transaction[[#This Row],[Reference Number]],barang_keluar[],4,FALSE),"")) -> SNK025 | E10: =IF(tbl_transaction[[#This Row],[Type]]="Inbound",VLOOKUP(tbl_transaction[[#This Row],[Reference Number]],barang_masuk[],5,FALSE),IF(tbl_transaction[[#This Row],[Type]]="Outbound",VLOOKUP(tbl_transaction[[#This Row],[Reference Number]],barang_keluar[],5,FALSE),"")) -> Qtela Snack Variant 25 | F10: =IF(tbl_transaction[[#This Row],[Type]]="Inbound",VLOOKUP(tbl_transaction[[#This Row],[Reference Number]],barang_masuk[],6,FALSE),IF(tbl_transaction[[#This Row],[Type]]="Outbound",VLOOKUP(tbl_transaction[[#This Row],[Reference Number]],barang_keluar[],6,FALSE),"")) -> 200 | G10: =IF(tbl_transaction[[#This Row],[Type]]="Inbound",VLOOKUP(tbl_transaction[[#This Row],[Reference Number]],barang_masuk[],7,FALSE),IF(tbl_transaction[[#This Row],[Type]]="Outbound",VLOOKUP(tbl_transaction[[#This Row],[Reference Number]],barang_keluar[],7,FALSE),"")) -> Pack | H10: =IF(tbl_transaction[[#This Row],[Type]]="Inbound",VLOOKUP(tbl_transaction[[#This Row],[Reference Number]],barang_masuk[],3,FALSE),IF(tbl_transaction[[#This Row],[Type]]="Outbound",VLOOKUP(tbl_transaction[[#This Row],[Reference Number]],barang_keluar[],3,FALSE),"")) -> PT Supplier 14 | I10: =IF(D10='Kartu Stok'!$B$2,COUNTIF($D$3:D10,'Kartu Stok'!$B$2),"")
A11: GR202600009 | B11: =IF(LEFT(tbl_transaction[[#This Row],[Reference Number]],2)="GR",VLOOKUP(tbl_transaction[[#This Row],[Reference Number]],barang_masuk[],2,FALSE),IF(LEFT(tbl_transaction[[#This Row],[Reference Number]],2)="DO",VLOOKUP(tbl_transaction[[#This Row],[Reference Number]],barang_keluar[],2,FALSE),"")) -> 46186 | C11: =IF(LEFT(A11,2)="GR","Inbound",IF(LEFT(A11,2)="DO","Outbound","")) -> Inbound | D11: =IF(tbl_transaction[[#This Row],[Type]]="Inbound",VLOOKUP(tbl_transaction[[#This Row],[Reference Number]],barang_masuk[],4,FALSE),IF(tbl_transaction[[#This Row],[Type]]="Outbound",VLOOKUP(tbl_transaction[[#This Row],[Reference Number]],barang_keluar[],4,FALSE),"")) -> SNK021 | E11: =IF(tbl_transaction[[#This Row],[Type]]="Inbound",VLOOKUP(tbl_transaction[[#This Row],[Reference Number]],barang_masuk[],5,FALSE),IF(tbl_transaction[[#This Row],[Type]]="Outbound",VLOOKUP(tbl_transaction[[#This Row],[Reference Number]],barang_keluar[],5,FALSE),"")) -> Qtela Snack Variant 21 | F11: =IF(tbl_transaction[[#This Row],[Type]]="Inbound",VLOOKUP(tbl_transaction[[#This Row],[Reference Number]],barang_masuk[],6,FALSE),IF(tbl_transaction[[#This Row],[Type]]="Outbound",VLOOKUP(tbl_transaction[[#This Row],[Reference Number]],barang_keluar[],6,FALSE),"")) -> 60 | G11: =IF(tbl_transaction[[#This Row],[Type]]="Inbound",VLOOKUP(tbl_transaction[[#This Row],[Reference Number]],barang_masuk[],7,FALSE),IF(tbl_transaction[[#This Row],[Type]]="Outbound",VLOOKUP(tbl_transaction[[#This Row],[Reference Number]],barang_keluar[],7,FALSE),"")) -> Pack | H11: =IF(tbl_transaction[[#This Row],[Type]]="Inbound",VLOOKUP(tbl_transaction[[#This Row],[Reference Number]],barang_masuk[],3,FALSE),IF(tbl_transaction[[#This Row],[Type]]="Outbound",VLOOKUP(tbl_transaction[[#This Row],[Reference Number]],barang_keluar[],3,FALSE),"")) -> PT Supplier 27 | I11: =IF(D11='Kartu Stok'!$B$2,COUNTIF($D$3:D11,'Kartu Stok'!$B$2),"")
A12: GR202600010 | B12: =IF(LEFT(tbl_transaction[[#This Row],[Reference Number]],2)="GR",VLOOKUP(tbl_transaction[[#This Row],[Reference Number]],barang_masuk[],2,FALSE),IF(LEFT(tbl_transaction[[#This Row],[Reference Number]],2)="DO",VLOOKUP(tbl_transaction[[#This Row],[Reference Number]],barang_keluar[],2,FALSE),"")) -> 46175 | C12: =IF(LEFT(A12,2)="GR","Inbound",IF(LEFT(A12,2)="DO","Outbound","")) -> Inbound | D12: =IF(tbl_transaction[[#This Row],[Type]]="Inbound",VLOOKUP(tbl_transaction[[#This Row],[Reference Number]],barang_masuk[],4,FALSE),IF(tbl_transaction[[#This Row],[Type]]="Outbound",VLOOKUP(tbl_transaction[[#This Row],[Reference Number]],barang_keluar[],4,FALSE),"")) -> PER006 | E12: =IF(tbl_transaction[[#This Row],[Type]]="Inbound",VLOOKUP(tbl_transaction[[#This Row],[Reference Number]],barang_masuk[],5,FALSE),IF(tbl_transaction[[#This Row],[Type]]="Outbound",VLOOKUP(tbl_transaction[[#This Row],[Reference Number]],barang_keluar[],5,FALSE),"")) -> Lifebuoy Personal Care Variant 6 | F12: =IF(tbl_transaction[[#This Row],[Type]]="Inbound",VLOOKUP(tbl_transaction[[#This Row],[Reference Number]],barang_masuk[],6,FALSE),IF(tbl_transaction[[#This Row],[Type]]="Outbound",VLOOKUP(tbl_transaction[[#This Row],[Reference Number]],barang_keluar[],6,FALSE),"")) -> 150 | G12: =IF(tbl_transaction[[#This Row],[Type]]="Inbound",VLOOKUP(tbl_transaction[[#This Row],[Reference Number]],barang_masuk[],7,FALSE),IF(tbl_transaction[[#This Row],[Type]]="Outbound",VLOOKUP(tbl_transaction[[#This Row],[Reference Number]],barang_keluar[],7,FALSE),"")) -> Bottle | H12: =IF(tbl_transaction[[#This Row],[Type]]="Inbound",VLOOKUP(tbl_transaction[[#This Row],[Reference Number]],barang_masuk[],3,FALSE),IF(tbl_transaction[[#This Row],[Type]]="Outbound",VLOOKUP(tbl_transaction[[#This Row],[Reference Number]],barang_keluar[],3,FALSE),"")) -> PT Supplier 10 | I12: =IF(D12='Kartu Stok'!$B$2,COUNTIF($D$3:D12,'Kartu Stok'!$B$2),"")
A13: GR202600011 | B13: =IF(LEFT(tbl_transaction[[#This Row],[Reference Number]],2)="GR",VLOOKUP(tbl_transaction[[#This Row],[Reference Number]],barang_masuk[],2,FALSE),IF(LEFT(tbl_transaction[[#This Row],[Reference Number]],2)="DO",VLOOKUP(tbl_transaction[[#This Row],[Reference Number]],barang_keluar[],2,FALSE),"")) -> 46120 | C13: =IF(LEFT(A13,2)="GR","Inbound",IF(LEFT(A13,2)="DO","Outbound","")) -> Inbound | D13: =IF(tbl_transaction[[#This Row],[Type]]="Inbound",VLOOKUP(tbl_transaction[[#This Row],[Reference Number]],barang_masuk[],4,FALSE),IF(tbl_transaction[[#This Row],[Type]]="Outbound",VLOOKUP(tbl_transaction[[#This Row],[Reference Number]],barang_keluar[],4,FALSE),"")) -> BAB020 | E13: =IF(tbl_transaction[[#This Row],[Type]]="Inbound",VLOOKUP(tbl_transaction[[#This Row],[Reference Number]],barang_masuk[],5,FALSE),IF(tbl_transaction[[#This Row],[Type]]="Outbound",VLOOKUP(tbl_transaction[[#This Row],[Reference Number]],barang_keluar[],5,FALSE),"")) -> Zwitsal Baby Care Variant 20 | F13: =IF(tbl_transaction[[#This Row],[Type]]="Inbound",VLOOKUP(tbl_transaction[[#This Row],[Reference Number]],barang_masuk[],6,FALSE),IF(tbl_transaction[[#This Row],[Type]]="Outbound",VLOOKUP(tbl_transaction[[#This Row],[Reference Number]],barang_keluar[],6,FALSE),"")) -> 40 | G13: =IF(tbl_transaction[[#This Row],[Type]]="Inbound",VLOOKUP(tbl_transaction[[#This Row],[Reference Number]],barang_masuk[],7,FALSE),IF(tbl_transaction[[#This Row],[Type]]="Outbound",VLOOKUP(tbl_transaction[[#This Row],[Reference Number]],barang_keluar[],7,FALSE),"")) -> Pack | H13: =IF(tbl_transaction[[#This Row],[Type]]="Inbound",VLOOKUP(tbl_transaction[[#This Row],[Reference Number]],barang_masuk[],3,FALSE),IF(tbl_transaction[[#This Row],[Type]]="Outbound",VLOOKUP(tbl_transaction[[#This Row],[Reference Number]],barang_keluar[],3,FALSE),"")) -> PT Supplier 11 | I13: =IF(D13='Kartu Stok'!$B$2,COUNTIF($D$3:D13,'Kartu Stok'!$B$2),"")
A14: GR202600012 | B14: =IF(LEFT(tbl_transaction[[#This Row],[Reference Number]],2)="GR",VLOOKUP(tbl_transaction[[#This Row],[Reference Number]],barang_masuk[],2,FALSE),IF(LEFT(tbl_transaction[[#This Row],[Reference Number]],2)="DO",VLOOKUP(tbl_transaction[[#This Row],[Reference Number]],barang_keluar[],2,FALSE),"")) -> 46152 | C14: =IF(LEFT(A14,2)="GR","Inbound",IF(LEFT(A14,2)="DO","Outbound","")) -> Inbound | D14: =IF(tbl_transaction[[#This Row],[Type]]="Inbound",VLOOKUP(tbl_transaction[[#This Row],[Reference Number]],barang_masuk[],4,FALSE),IF(tbl_transaction[[#This Row],[Type]]="Outbound",VLOOKUP(tbl_transaction[[#This Row],[Reference Number]],barang_keluar[],4,FALSE),"")) -> PER005 | E14: =IF(tbl_transaction[[#This Row],[Type]]="Inbound",VLOOKUP(tbl_transaction[[#This Row],[Reference Number]],barang_masuk[],5,FALSE),IF(tbl_transaction[[#This Row],[Type]]="Outbound",VLOOKUP(tbl_transaction[[#This Row],[Reference Number]],barang_keluar[],5,FALSE),"")) -> Pepsodent Personal Care Variant 5 | F14: =IF(tbl_transaction[[#This Row],[Type]]="Inbound",VLOOKUP(tbl_transaction[[#This Row],[Reference Number]],barang_masuk[],6,FALSE),IF(tbl_transaction[[#This Row],[Type]]="Outbound",VLOOKUP(tbl_transaction[[#This Row],[Reference Number]],barang_keluar[],6,FALSE),"")) -> 40 | G14: =IF(tbl_transaction[[#This Row],[Type]]="Inbound",VLOOKUP(tbl_transaction[[#This Row],[Reference Number]],barang_masuk[],7,FALSE),IF(tbl_transaction[[#This Row],[Type]]="Outbound",VLOOKUP(tbl_transaction[[#This Row],[Reference Number]],barang_keluar[],7,FALSE),"")) -> Bottle | H14: =IF(tbl_transaction[[#This Row],[Type]]="Inbound",VLOOKUP(tbl_transaction[[#This Row],[Reference Number]],barang_masuk[],3,FALSE),IF(tbl_transaction[[#This Row],[Type]]="Outbound",VLOOKUP(tbl_transaction[[#This Row],[Reference Number]],barang_keluar[],3,FALSE),"")) -> PT Supplier 25 | I14: =IF(D14='Kartu Stok'!$B$2,COUNTIF($D$3:D14,'Kartu Stok'!$B$2),"")
... A4002: DO202602500 | B4002: =IF(LEFT(tbl_transaction[[#This Row],[Reference Number]],2)="GR",VLOOKUP(tbl_transaction[[#This Row],[Reference Number]],barang_masuk[],2,FALSE),IF(LEFT(tbl_transaction[[#This Row],[Reference Number]],2)="DO",VLOOKUP(tbl_transaction[[#This Row],[Reference Number]],barang_keluar[],2,FALSE),"")) -> 46061 | C4002: =IF(LEFT(A4002,2)="GR","Inbound",IF(LEFT(A4002,2)="DO","Outbound","")) -> Outbound | D4002: =IF(tbl_transaction[[#This Row],[Type]]="Inbound",VLOOKUP(tbl_transaction[[#This Row],[Reference Number]],barang_masuk[],4,FALSE),IF(tbl_transaction[[#This Row],[Type]]="Outbound",VLOOKUP(tbl_transaction[[#This Row],[Reference Number]],barang_keluar[],4,FALSE),"")) -> PER002 | E4002: =IF(tbl_transaction[[#This Row],[Type]]="Inbound",VLOOKUP(tbl_transaction[[#This Row],[Reference Number]],barang_masuk[],5,FALSE),IF(tbl_transaction[[#This Row],[Type]]="Outbound",VLOOKUP(tbl_transaction[[#This Row],[Reference Number]],barang_keluar[],5,FALSE),"")) -> Lifebuoy Personal Care Variant 2 | F4002: =IF(tbl_transaction[[#This Row],[Type]]="Inbound",VLOOKUP(tbl_transaction[[#This Row],[Reference Number]],barang_masuk[],6,FALSE),IF(tbl_transaction[[#This Row],[Type]]="Outbound",VLOOKUP(tbl_transaction[[#This Row],[Reference Number]],barang_keluar[],6,FALSE),"")) -> 10 | G4002: =IF(tbl_transaction[[#This Row],[Type]]="Inbound",VLOOKUP(tbl_transaction[[#This Row],[Reference Number]],barang_masuk[],7,FALSE),IF(tbl_transaction[[#This Row],[Type]]="Outbound",VLOOKUP(tbl_transaction[[#This Row],[Reference Number]],barang_keluar[],7,FALSE),"")) -> Bottle | H4002: =IF(tbl_transaction[[#This Row],[Type]]="Inbound",VLOOKUP(tbl_transaction[[#This Row],[Reference Number]],barang_masuk[],3,FALSE),IF(tbl_transaction[[#This Row],[Type]]="Outbound",VLOOKUP(tbl_transaction[[#This Row],[Reference Number]],barang_keluar[],3,FALSE),"")) -> Outlet 075 | I4002: =IF(D4002='Kartu Stok'!$B$2,COUNTIF($D$3:D4002,'Kartu Stok'!$B$2),"")

Sheet Kartu Stok
A1: STOCK CARD
A2: Pilih Barang | B2: BAB018 | E2: Stock on Hand
A3: Nama Barang | B3: =VLOOKUP(B2,master_barang[],2,FALSE) -> MamyPoko Baby Care Variant 18 | E3: =E7+SUM($C$8:$C$1000)-SUM($D$8:$D$1000) -> 1172
A4: Satuan | B4: =VLOOKUP(B2,master_barang[],5,FALSE) -> Pack
A6: Date | B6: Reference Number | C6: Inbound | D6: Outbound | E6: Stock on Hand
A7: Saldo awal | E7: =VLOOKUP(B2,stok_awal[],2,FALSE) -> 906
A8: =IFERROR(INDEX(Data_Transaksi!$B$3:$B$5000,MATCH(ROWS($A$8:A8),Data_Transaksi!$I$3:$I$5000,0)),"") -> 46088 | B8: =IFERROR(INDEX(Data_Transaksi!$A$3:$A$5000,MATCH(ROWS($A$8:A8),Data_Transaksi!$I$3:$I$5000,0)),"") -> GR202600001 | C8: =IFERROR(IF(INDEX(Data_Transaksi!$C$3:$C$5000,MATCH(ROWS($A$8:A8),Data_Transaksi!$I$3:$I$5000,0))="Inbound",INDEX(Data_Transaksi!$F$3:$F$5000,MATCH(ROWS($A$8:A8),Data_Transaksi!$I$3:$I$5000,0)),""),"") -> 20 | D8: =IFERROR(IF(INDEX(Data_Transaksi!$C$3:$C$5000,MATCH(ROWS($A$8:A8),Data_Transaksi!$I$3:$I$5000,0))="Outbound",INDEX(Data_Transaksi!$F$3:$F$5000,MATCH(ROWS($A$8:A8),Data_Transaksi!$I$3:$I$5000,0)),""),"") | E8: =IF(A8="","",E7+IF(C8="",0,C8)-IF(D8="",0,D8)) -> 926
A9: =IFERROR(INDEX(Data_Transaksi!$B$3:$B$5000,MATCH(ROWS($A$8:A9),Data_Transaksi!$I$3:$I$5000,0)),"") -> 46054 | B9: =IFERROR(INDEX(Data_Transaksi!$A$3:$A$5000,MATCH(ROWS($A$8:A9),Data_Transaksi!$I$3:$I$5000,0)),"") -> GR202600211 | C9: =IFERROR(IF(INDEX(Data_Transaksi!$C$3:$C$5000,MATCH(ROWS($A$8:A9),Data_Transaksi!$I$3:$I$5000,0))="Inbound",INDEX(Data_Transaksi!$F$3:$F$5000,MATCH(ROWS($A$8:A9),Data_Transaksi!$I$3:$I$5000,0)),""),"") -> 40 | D9: =IFERROR(IF(INDEX(Data_Transaksi!$C$3:$C$5000,MATCH(ROWS($A$8:A9),Data_Transaksi!$I$3:$I$5000,0))="Outbound",INDEX(Data_Transaksi!$F$3:$F$5000,MATCH(ROWS($A$8:A9),Data_Transaksi!$I$3:$I$5000,0)),""),"") | E9: =IF(A9="","",E8+IF(C9="",0,C9)-IF(D9="",0,D9)) -> 966
A10: =IFERROR(INDEX(Data_Transaksi!$B$3:$B$5000,MATCH(ROWS($A$8:A10),Data_Transaksi!$I$3:$I$5000,0)),"") -> 46157 | B10: =IFERROR(INDEX(Data_Transaksi!$A$3:$A$5000,MATCH(ROWS($A$8:A10),Data_Transaksi!$I$3:$I$5000,0)),"") -> GR202600214 | C10: =IFERROR(IF(INDEX(Data_Transaksi!$C$3:$C$5000,MATCH(ROWS($A$8:A10),Data_Transaksi!$I$3:$I$5000,0))="Inbound",INDEX(Data_Transaksi!$F$3:$F$5000,MATCH(ROWS($A$8:A10),Data_Transaksi!$I$3:$I$5000,0)),""),"") -> 50 | D10: =IFERROR(IF(INDEX(Data_Transaksi!$C$3:$C$5000,MATCH(ROWS($A$8:A10),Data_Transaksi!$I$3:$I$5000,0))="Outbound",INDEX(Data_Transaksi!$F$3:$F$5000,MATCH(ROWS($A$8:A10),Data_Transaksi!$I$3:$I$5000,0)),""),"") | E10: =IF(A10="","",E9+IF(C10="",0,C10)-IF(D10="",0,D10)) -> 1016
A11: =IFERROR(INDEX(Data_Transaksi!$B$3:$B$5000,MATCH(ROWS($A$8:A11),Data_Transaksi!$I$3:$I$5000,0)),"") -> 46062 | B11: =IFERROR(INDEX(Data_Transaksi!$A$3:$A$5000,MATCH(ROWS($A$8:A11),Data_Transaksi!$I$3:$I$5000,0)),"") -> GR202600305 | C11: =IFERROR(IF(INDEX(Data_Transaksi!$C$3:$C$5000,MATCH(ROWS($A$8:A11),Data_Transaksi!$I$3:$I$5000,0))="Inbound",INDEX(Data_Transaksi!$F$3:$F$5000,MATCH(ROWS($A$8:A11),Data_Transaksi!$I$3:$I$5000,0)),""),"") -> 30 | D11: =IFERROR(IF(INDEX(Data_Transaksi!$C$3:$C$5000,MATCH(ROWS($A$8:A11),Data_Transaksi!$I$3:$I$5000,0))="Outbound",INDEX(Data_Transaksi!$F$3:$F$5000,MATCH(ROWS($A$8:A11),Data_Transaksi!$I$3:$I$5000,0)),""),"") | E11: =IF(A11="","",E10+IF(C11="",0,C11)-IF(D11="",0,D11)) -> 1046
